Workbook

Sheet 管理者_ログイン画面
B2: 【PC】管理者_ログイン画面
B4: 項目作成時アプリバージョン | D4: =定義!$B$4 -> 1.0.4
B5: 総項目数 | D5: =COUNT($B15:$B32) -> 18
B6: 達成率 | D6: =D9 / COUNT($B15:$B32) -> 0
B7: 未着手 | D7: =COUNTIF($H$15:$H$32,"未着手") -> 18
B8: 進行中 | D8: =COUNTIF($H$15:$H$32,"進行中") -> 0
B9: 確認完了 | D9: =COUNTIF($H$15:$H$32,"確認完了") -> 0
B10: 確認不可 | D10: =COUNTIF($H$15:$H$32,"確認不可") -> 0
B11: NG | D11: =COUNTIF($H$15:$H$32,"NG") -> 0
B13: 項番 | C13: 確認内容 | H13: 確認結果 | I13: 確認ver | J13: 確認日 | K13: 確認者 | L13: 端末 | M13: ブラウザ | N13: 備考
C14: 名称 | D14: タイプ | E14: 条件 | F14: 状態 | G14: 期待値
B15: 1 | C15: アプリケーションロゴ | D15: 画像 | E15: - | F15: - | G15: 画面左上に表示されており、画像に欠けや乱れがないこと | H15: 未着手
B16: 2 | C16: 画面タイトル | D16: 見出し | E16: - | F16: - | G16: 画面左側に「管理者画面にログイン」とテキスト表示されていること | H16: 未着手
B17: 3 | C17: アプリケーションバージョン | D17: 文字列 | E17: - | F17: - | G17: 画面左下に正しいアプリのバージョンが表示されていること | H17: 未着手
B18: 4 | C18: 開発団体 | D18: 文字列 | E18: - | F18: - | G18: 画面左下に「開発 劇団抜きにくい釘」と表示されていること | H18: 未着手
B19: 5 | C19: ログイン方法 | D19: 文字列 | E19: - | F19: - | G19: 画面右側に名称の内容と同じテキストが表示されていること | H19: 未着手
B20: 6 | C20: ログイン方法 | D20: プルダウンボックス | E20: - | F20: - | G20: 画面右側にログイン方法を選択するプルダウンボックスが表示されていること | H20: 未着手
B21: 7 | C21: ユーザーID | D21: オプション | E21: - | F21: - | G21: ログイン方法選択プルダウンボックス内に「ユーザーID」が表示されていること | H21: 未着手
B22: 8 | C22: メールアドレス | D22: オプション | E22: - | F22: - | G22: ログイン方法選択プルダウンボックス内に「メールアドレス」が表示されていること | H22: 未着手
B23: 9 | C23: ユーザーID | D23: 文字列 | E23: ログイン方法にて、「ユーザーID」を選択 | F23: - | G23: 画面右側に名称の内容と同じテキストが表示されていること | H23: 未着手
B24: 10 | C24: ユーザーID入力欄 | D24: 入力ボックス | E24: ログイン方法にて、「ユーザーID」を選択 | F24: - | G24: 画面右側に当該項目の入力欄が表示されていること | H24: 未着手
B25: 11 | C25: メールアドレス | D25: 文字列 | E25: ログイン方法にて、「メールアドレス」を選択 | F25: - | G25: 画面右側に名称の内容と同じテキストが表示されていること | H25: 未着手
B26: 12 | C26: メールアドレス入力欄 | D26: 入力ボックス | E26: ログイン方法にて、「メールアドレス」を選択 | F26: - | G26: 画面右側に当該項目の入力欄が表示されていること | H26: 未着手
... B32: 18 | C32: その他要素 | D32: - | E32: - | F32: - | G32: 上記に記載の無い不要な要素が表示されていないこと | H32: 未着手
B35: 【mobile】管理者_ログイン画面
B37: 項目作成時アプリバージョン | D37: =定義!$B$4 -> 1.0.4
B38: 総項目数 | D38: =COUNT($B48:$B66) -> 19
B39: 達成率 | D39: =D42 / COUNT($B48:$B66) -> 0
B40: 未着手 | D40: =COUNTIF($H$48:$H$66,"未着手") -> 19
B41: 進行中 | D41: =COUNTIF($H$48:$H$66,"進行中") -> 0
B42: 確認完了 | D42: =COUNTIF($H$48:$H$66,"確認完了") -> 0
B43: 確認不可 | D43: =COUNTIF($H$48:$H$66,"確認不可") -> 0
B44: NG | D44: =COUNTIF($H$48:$H$66,"NG") -> 0
B46: 項番 | C46: 確認内容 | H46: 確認結果 | I46: 確認ver | J46: 確認日 | K46: 確認者 | L46: 端末 | M46: ブラウザ | N46: 備考
C47: 名称 | D47: タイプ | E47: 条件 | F47: 状態 | G47: 期待値
B48: 1 | C48: アプリケーションロゴ | D48: 画像 | E48: - | F48: - | G48: 画像に欠けや乱れがないこと | H48: 未着手
B49: 2 | C49: アプリケーションタイトル | D49: 見出し | E49: - | F49: - | G49: 「予約管理システム Grobe」とテキスト表示されていること | H49: 未着手
B50: 3 | C50: 画面タイトル | D50: 見出し | E50: - | F50: - | G50: 「管理者ログイン画面」とテキスト表示されていること | H50: 未着手
B51: 4 | C51: ログイン方法 | D51: 文字列 | E51: - | F51: - | G51: 名称の内容と同じテキストが表示されていること | H51: 未着手
B52: 5 | C52: ログイン方法 | D52: プルダウンボックス | E52: - | F52: - | G52: ログイン方法を選択するプルダウンボックスが表示されていること | H52: 未着手
...

Sheet 管理者_新規ユーザー作成画面
B2: 【PC】管理者_新規ユーザー作成画面
B4: 項目作成時アプリバージョン | D4: =定義!B4 -> 1.0.4
B5: 総項目数 | D5: =COUNT(B15:B82) -> 68
B6: 達成率 | D6: =D9 / COUNT(B15:B82) -> 0
B7: 未着手 | D7: =COUNTIF($H$15:$H$82,"未着手") -> 68
B8: 進行中 | D8: =COUNTIF($H$15:$H$82,"進行中") -> 0
B9: 確認完了 | D9: =COUNTIF($H$15:$H$82,"確認完了") -> 0
B10: 確認不可 | D10: =COUNTIF($H$15:$H$82,"確認不可") -> 0
B11: NG | D11: =COUNTIF($H$15:$H$82,"NG") -> 0
B13: 項番 | C13: 確認内容 | H13: 確認結果 | I13: 確認ver | J13: 確認日 | K13: 確認者 | L13: 端末 | M13: ブラウザ | N13: 備考
C14: 名称 | D14: タイプ | E14: 条件 | F14: 状態 | G14: 期待値
B15: 1 | C15: アプリケーションロゴ | D15: 画像 | E15: - | F15: - | G15: 画面左上に表示されており、画像に欠けや乱れがないこと | H15: 未着手
B16: 2 | C16: 画面タイトル | D16: 見出し | E16: - | F16: - | G16: 画面左側に名称の内容と同じテキストが表示されていること | H16: 未着手
B17: 3 | C17: アプリケーションバージョン | D17: 文字列 | E17: - | F17: - | G17: 画面左下に正しいアプリのバージョンが表示されていること | H17: 未着手
B18: 4 | C18: 開発団体 | D18: 文字列 | E18: - | F18: - | G18: 画面左下に「開発 劇団抜きにくい釘」と表示されていること | H18: 未着手
B19: 5 | C19: メールアドレス | D19: 文字列 | E19: - | F19: - | G19: 画面右側に名称の内容と同じテキストが表示されていること | H19: 未着手
B20: 6 | C20: メールアドレス入力欄 | D20: 入力ボックス | E20: - | F20: - | G20: 画面右側に当該項目の入力欄が表示されていること | H20: 未着手
B21: 7 | C21: 注意事項 | D21: プレースホルダー | E21: - | F21: - | G21: メールアドレス入力ボックス内に「登録済みアドレスは使用不可」と表示されていること | H21: 未着手
B22: 8 | C22: 確認 | D22: ボタン | E22: - | F22: - | G22: 画面右側に名称の内容と同じボタンが表示されていること | H22: 未着手
B23: 9 | C23: キャンセルリンク | D23: 文字列 | E23: - | F23: - | G23: 画面右側に「キャンセル」と表示されていること 「キャンセル」部分はページリンクを示す色で表示されていること | H23: 未着手
B24: 10 | C24: ユーザーID | D24: 文字列 | E24: - | F24: - | G24: 画面右側に名称の内容と同じテキストが表示されていること | H24: 未着手
B25: 11 | C25: ユーザーID入力欄 | D25: 入力ボックス | E25: - | F25: - | G25: 画面右側に当該項目の入力欄が表示されていること | H25: 未着手
B26: 12 | C26: 確定 | D26: ボタン | E26: - | F26: - | G26: 画面右側に名称の内容と同じボタンが表示されていること | H26: 未着手
... B39: 25 | C39: パスワード入力欄 | D39: 入力ボックス | E39: - | F39: - | G39: 画面右側に当該項目の入力欄が表示されていること | H39: 未着手
B40: 26 | C40: パスワード入力文字列 | D40: 入力内容 | E40: パスワード入力欄にて任意の文字列を入力 | G40: 入力した文字が文字隠れ表示となること | H40: 未着手
B41: 27 | C41: パスワード再入力 | D41: 文字列 | E41: - | F41: - | G41: 画面右側に名称の内容と同じテキストが表示されていること | H41: 未着手
B42: 28 | C42: パスワード再入力欄 | D42: 入力ボックス | E42: - | F42: - | G42: 画面右側に当該項目の入力欄が表示されていること | H42: 未着手
B43: 29 | C43: パスワード再入力文字列 | D43: 入力内容 | E43: パスワード再入力欄にて任意の文字列を入力 | G43: 入力した文字が文字隠れ表示となること | H43: 未着手
B44: 30 | C44: 確定 | D44: ボタン | E44: - | F44: - | G44: 画面右側に名称の内容と同じボタンが表示されていること | H44: 未着手
B45: 31 | C45: 戻る | D45: ボタン | E45: - | F45: - | G45: 画面右側に名称の内容と同じボタンが表示されていること | H45: 未着手
B46: 32 | C46: キャンセルリンク | D46: 文字列 | E46: - | F46: - | G46: 画面右側に「キャンセル」と表示されていること 「キャンセル」部分はページリンクを示す色で表示されていること | H46: 未着手
B47: 33 | C47: 電話番号 | D47: 文字列 | E47: - | F47: - | G47: 画面右側に名称の内容と同じテキストが表示されていること | H47: 未着手
B48: 34 | C48: 電話番号入力欄 | D48: 入力ボックス | E48: - | F48: - | G48: 画面右側に当該項目の入力欄が表示されていること | H48: 未着手
B49: 35 | C49: 電話番号注意事項 | D49: プレースホルダー | E49: - | F49: - | G49: 電話番号入力ボックス内に「任意入力」と表示されていること | H49: 未着手
B50: 36 | C50: 生年月日 | D50: 文字列 | E50: - | F50: - | G50: 画面右側に名称の内容と同じテキストが表示されていること | H50: 未着手
B51: 37 | C51: 生年月日入力欄 | D51: 入力ボックス | E51: - | F51: - | G51: 画面右側に当該項目の入力欄が表示されていること | H51: 未着手
B52: 38 | C52: 年齢を非公開にする | D52: 文字列 | E52: - | F52: - | G52: 画面右側に名称の内容と同じテキストが表示されていること | H52: 未着手
B53: 39 | C53: 予約者アカウントと併用する | D53: チェックボックス | E53: - | F53: - | G53: 画面右側に当該項目のチェックボックスが表示されていること | H53: 未着手
B54: 40 | C54: メッセージ | D54: 文字列 | E54: - | F54: - | G54: 「※お客様として公演を予約する際、このアカウントが使用可能になります」 | H54: 未着手
B55: 41 | C55: 確定 | D55: ボタン | E55: - | F55: - | G55: 画面右側に名称の内容と同じボタンが表示されていること | H55: 未着手
...

Sheet 管理者_アカウント作成送信メール
B2: 【PC】管理者_アカウント作成送信メール
B4: 項目作成時アプリバージョン | D4: =定義!B4 -> 1.0.4
B5: 総項目数 | D5: =COUNT(B15:B17) -> 3
B6: 達成率 | D6: =D9 / COUNT(B15:B17) -> 0
B7: 未着手 | D7: =COUNTIF($H$15:$H$17,"未着手") -> 3
B8: 進行中 | D8: =COUNTIF($H$15:$H$17,"進行中") -> 0
B9: 確認完了 | D9: =COUNTIF($H$15:$H$17,"確認完了") -> 0
B10: 確認不可 | D10: =COUNTIF($H$15:$H$17,"確認不可") -> 0
B11: NG | D11: =COUNTIF($H$15:$H$17,"NG") -> 0
B13: 項番 | C13: 確認内容 | H13: 確認結果 | I13: 確認ver | J13: 確認日 | K13: 確認者 | L13: 端末 | M13: ブラウザ | N13: 備考
C14: 名称 | D14: タイプ | E14: 条件 | F14: 状態 | G14: 期待値
B15: 1 | C15: 送信元 | D15: メールアドレス | E15: - | F15: - | G15: 「globe.reserveticket@gmail.com」からメールが届くこと | H15: 未着手
B16: 2 | C16: メッセージ本文 | D16: 文字列 | E16: - | F16: - | G16: 「こんにちは！ Grobe運営事務局です。 まだアカウント登録は完了しておりません。下記URLから手続きを完了してください。」とテキスト表示されていること | H16: 未着手
B17: 3 | C17: アカウント作成リンク | D17: 文字列 | E17: - | F17: - | G17: アカウント作成画面へのリンク文字列が表示されていること | H17: 未着手
B20: 【mobile】管理者_アカウント作成送信メール
B22: 項目作成時アプリバージョン | D22: =定義!B87 -> 0
B23: 総項目数 | D23: =COUNT($B33:$B35) -> 3
B24: 達成率 | D24: =D27 / COUNT($B33:$B35) -> 0
B25: 未着手 | D25: =COUNTIF($H$33:$H$35,"未着手") -> 3
B26: 進行中 | D26: =COUNTIF($H$33:$H$35,"進行中") -> 0
B27: 確認完了 | D27: =COUNTIF($H$33:$H$35,"確認完了") -> 0
B28: 確認不可 | D28: =COUNTIF($H$33:$H$35,"確認不可") -> 0
B29: NG | D29: =COUNTIF($H$33:$H$35,"NG") -> 0
B31: 項番 | C31: 確認内容 | H31: 確認結果 | I31: 確認ver | J31: 確認日 | K31: 確認者 | L31: 端末 | M31: ブラウザ | N31: 備考
C32: 名称 | D32: タイプ | E32: 条件 | F32: 状態 | G32: 期待値
B33: 1 | C33: 送信元 | D33: メールアドレス | E33: - | F33: - | G33: 「globe.reserveticket@gmail.com」からメールが届くこと | H33: 未着手
B34: 2 | C34: メッセージ本文 | D34: 文字列 | E34: - | F34: - | G34: 「こんにちは！ Grobe運営事務局です。 まだアカウント登録は完了しておりません。下記URLから手続きを完了してください。」とテキスト表示されていること | H34: 未着手
B35: 3 | C35: アカウント作成リンク | D35: 文字列 | E35: - | F35: - | G35: アカウント作成画面へのリンク文字列が表示されていること | H35: 未着手

Sheet 管理者_ホーム画面
B2: 【PC】管理者_ホーム画面
B4: 項目作成時アプリバージョン | D4: =定義!B4 -> 1.0.4
B5: 総項目数 | D5: =COUNT($B$15:$B$46) -> 32
B6: 達成率 | D6: =D9 / COUNT($B$15:$B$46) -> 0
B7: 未着手 | D7: =COUNTIF($I$15:$I$46,"未着手") -> 32
B8: 進行中 | D8: =COUNTIF($I$15:$I$46,"進行中") -> 0
B9: 確認完了 | D9: =COUNTIF($I$15:$I$46,"確認完了") -> 0
B10: 確認不可 | D10: =COUNTIF($I$15:$I$46,"確認不可") -> 0
B11: NG | D11: =COUNTIF($I$15:$I$46,"NG") -> 0
B13: 項番 | C13: 確認内容 | I13: 確認結果 | J13: 確認ver | K13: 確認日 | L13: 確認者 | M13: 端末 | N13: ブラウザ | O13: 備考
C14: 名称 | D14: 領域 | E14: タイプ | F14: 条件 | G14: 状態 | H14: 期待値
B15: 1 | C15: アプリケーションロゴ | D15: メニュー | E15: 画像 | F15: - | G15: - | H15: 画面左側に表示されており画像に欠けや乱れがないこと | I15: 未着手
B16: 2 | C16: 画面タイトル | D16: メニュー | E16: 見出し | F16: - | G16: - | H16: 画面左側に「管理者メニュー」とテキスト表示されていること | I16: 未着手
B17: 3 | C17: 公演メニュー | D17: メニュー | E17: メニュー見出し | F17: - | G17: - | H17: 画面左側に「公演メニュー」とテキスト表示されていること | I17: 未着手
B18: 4 | C18: 公演名 | D18: メニュー | E18: メニューリンク | F18: - | G18: - | H18: 画面左側に設定した公演名がテキスト表示されていること | I18: 未着手
B19: 5 | C19: 公演基本情報 | D19: メニュー | E19: メニューリンク | F19: 公演名を押下 | G19: - | H19: 画面左側に「票券」とテキスト表示されていること | I19: 未着手
B20: 6 | C20: 予約フォーム作成 | D20: メニュー | E20: メニューリンク | F20: 公演名を押下 | G20: - | H20: 画面左側に「票券」とテキスト表示されていること | I20: 未着手
B21: 7 | C21: 座席設定 | D21: メニュー | E21: メニューリンク | F21: 公演名を押下 | G21: - | H21: 画面左側に「票券」とテキスト表示されていること | I21: 未着手
B22: 8 | C22: 宣伝情報 | D22: メニュー | E22: メニューリンク | F22: 公演名を押下 | G22: - | H22: 画面左側に「票券」とテキスト表示されていること | I22: 未着手
B23: 9 | C23: 公演メンバー | D23: メニュー | E23: メニューリンク | F23: 公演名を押下 | G23: - | H23: 画面左側に「票券」とテキスト表示されていること | I23: 未着手
B24: 10 | C24: 票券管理 | D24: メニュー | E24: メニューリンク | F24: - | G24: - | H24: 画面左側に「票券」とテキスト表示されていること | I24: 未着手
B25: 11 | C25: 予約一覧 | D25: メニュー | E25: メニューリンク | F25: 票券管理を押下 | G25: - | H25: 画面左側に「票券」とテキスト表示されていること | I25: 未着手
B26: 12 | C26: 予約枚数集計 | D26: メニュー | E26: メニューリンク | F26: 票券管理を押下 | G26: - | H26: 画面左側に「票券」とテキスト表示されていること | I26: 未着手
... B46: 32 | C46: お知らせ内容 | D46: コンテンツ | E46: 文字列 | F46: - | G46: - | H46: 画面タイトルの下にお知らせの内容がテキスト表示されていること | I46: 未着手
B49: 【mobile】管理者_ホーム画面
B51: 項目作成時アプリバージョン | D51: =定義!B87 -> 0
B52: 総項目数 | D52: =COUNT($B62:$B68) -> 7
B53: 達成率 | D53: =D56 / COUNT($B62:$B68) -> 0
B54: 未着手 | D54: =COUNTIF($I$62:$I$68,"未着手") -> 7
B55: 進行中 | D55: =COUNTIF($I$62:$I$68,"進行中") -> 0
B56: 確認完了 | D56: =COUNTIF($I$62:$I$68,"確認完了") -> 0
B57: 確認不可 | D57: =COUNTIF($I$62:$I$68,"確認不可") -> 0
B58: NG | D58: =COUNTIF($I$62:$I$68,"NG") -> 0
B60: 項番 | C60: 確認内容 | I60: 確認結果 | J60: 確認ver | K60: 確認日 | L60: 確認者 | M60: 端末 | N60: ブラウザ | O60: 備考
C61: 名称 | D61: 領域 | E61: タイプ | F61: 条件 | G61: 状態 | H61: 期待値
B62: 1 | C62: アプリケーションロゴ | E62: 画像 | F62: - | G62: - | H62: 画像に欠けや乱れがないこと | I62: 未着手
B63: 2 | C63: ユーザーメニュー | E63: アイコン | F63: - | G63: - | H63: 画像に欠けや乱れがないこと | I63: 未着手
B64: 3 | C64: ホーム | E64: メニューリンク | F64: - | G64: - | H64: 「ホーム」とテキスト表示されていること | I64: 未着手
B65: 4 | C65: 公演メニュー | E65: メニューリンク | F65: - | G65: - | H65: 「公演メニュー」とテキスト表示されていること | I65: 未着手
B66: 5 | C66: 団体メニュー | E66: メニューリンク | F66: - | G66: - | H66: 「団体メニュー」とテキスト表示されていること | I66: 未着手
...

Sheet 定義
A1: 定義リスト | D1: 未着手 | E1: chrome
A2: 項目 | B2: 内容 | D2: 進行中 | E2: safari
A3: アプリケーション名 | B3: Grobe | D3: 確認完了 | E3: Firefox
A4: ver | B4: 1.0.4 | D4: 確認不可 | E4: Edge
D5: NG | E5: Brave
